[2024-10-03T10:47:07.691+0530] {local_task_job_runner.py:123} INFO - ::group::Pre task execution logs
[2024-10-03T10:47:07.705+0530] {taskinstance.py:2612} INFO - Dependencies all met for dep_context=non-requeueable deps ti=<TaskInstance: data_ingestion_dag.validate_data manual__2024-10-03T05:16:45.265780+00:00 [queued]>
[2024-10-03T10:47:07.712+0530] {taskinstance.py:2612} INFO - Dependencies all met for dep_context=requeueable deps ti=<TaskInstance: data_ingestion_dag.validate_data manual__2024-10-03T05:16:45.265780+00:00 [queued]>
[2024-10-03T10:47:07.712+0530] {taskinstance.py:2865} INFO - Starting attempt 1 of 2
[2024-10-03T10:47:07.739+0530] {taskinstance.py:2888} INFO - Executing <Task(PythonOperator): validate_data> on 2024-10-03 05:16:45.265780+00:00
[2024-10-03T10:47:07.744+0530] {standard_task_runner.py:72} INFO - Started process 12972 to run task
[2024-10-03T10:47:07.748+0530] {standard_task_runner.py:104} INFO - Running: ['airflow', 'tasks', 'run', 'data_ingestion_dag', 'validate_data', 'manual__2024-10-03T05:16:45.265780+00:00', '--job-id', '40', '--raw', '--subdir', 'DAGS_FOLDER/data_ingestion_dag.py', '--cfg-path', '/tmp/tmp9zxhc4g0']
[2024-10-03T10:47:07.751+0530] {standard_task_runner.py:105} INFO - Job 40: Subtask validate_data
[2024-10-03T10:47:07.807+0530] {task_command.py:467} INFO - Running <TaskInstance: data_ingestion_dag.validate_data manual__2024-10-03T05:16:45.265780+00:00 [running]> on host Nithesh-Kumar.localdomain
[2024-10-03T10:47:07.932+0530] {taskinstance.py:3131} INFO - Exporting env vars: AIRFLOW_CTX_DAG_OWNER='airflow' AIRFLOW_CTX_DAG_ID='data_ingestion_dag' AIRFLOW_CTX_TASK_ID='validate_data' AIRFLOW_CTX_EXECUTION_DATE='2024-10-03T05:16:45.265780+00:00' AIRFLOW_CTX_TRY_NUMBER='1' AIRFLOW_CTX_DAG_RUN_ID='manual__2024-10-03T05:16:45.265780+00:00'
[2024-10-03T10:47:07.935+0530] {taskinstance.py:731} INFO - ::endgroup::
[2024-10-03T10:47:08.051+0530] {file_data_context.py:222} INFO - FileDataContext loading fluent config
[2024-10-03T10:47:08.056+0530] {config.py:187} INFO - Loading 'datasources' ->
[]
[2024-10-03T10:48:24.492+0530] {local_task_job_runner.py:245} INFO - ::endgroup::
[2024-10-03T10:48:24.505+0530] {process_utils.py:132} INFO - Sending Signals.SIGTERM to group 12972. PIDs of all processes in the group: [12972]
[2024-10-03T10:48:24.508+0530] {process_utils.py:87} INFO - Sending the signal Signals.SIGTERM to group 12972
[2024-10-03T10:48:29.439+0530] {local_task_job_runner.py:123} INFO - ::group::Pre task execution logs
[2024-10-03T10:48:29.447+0530] {taskinstance.py:2602} INFO - Dependencies not met for <TaskInstance: data_ingestion_dag.validate_data manual__2024-10-03T05:16:45.265780+00:00 [running]>, dependency 'Task Instance Not Running' FAILED: Task is in the running state
[2024-10-03T10:48:29.452+0530] {taskinstance.py:2602} INFO - Dependencies not met for <TaskInstance: data_ingestion_dag.validate_data manual__2024-10-03T05:16:45.265780+00:00 [running]>, dependency 'Task Instance State' FAILED: Task is in the 'running' state.
[2024-10-03T10:48:29.453+0530] {local_task_job_runner.py:166} INFO - Task is not able to be run
[2024-10-03T10:49:21.047+0530] {taskinstance.py:3092} ERROR - Received SIGTERM. Terminating subprocesses.
[2024-10-03T10:49:21.068+0530] {taskinstance.py:3310} ERROR - Task failed with exception
Traceback (most recent call last):
  File "/home/username/.local/lib/python3.10/site-packages/sqlalchemy/pool/base.py", line 686, in __connect
    self.dbapi_connection = connection = pool._invoke_creator(self)
  File "/home/username/.local/lib/python3.10/site-packages/sqlalchemy/engine/create.py", line 574, in connect
    return dialect.connect(*cargs, **cparams)
  File "/home/username/.local/lib/python3.10/site-packages/sqlalchemy/engine/default.py", line 598, in connect
    return self.dbapi.connect(*cargs, **cparams)
  File "/home/username/.local/lib/python3.10/site-packages/psycopg2/__init__.py", line 122, in connect
    conn = _connect(dsn, connection_factory=connection_factory, **kwasync)
psycopg2.OperationalError: connection to server at "172.24.249.103", port 5432 failed: Connection timed out
	Is the server running on that host and accepting TCP/IP connections?


During handling of the above exception, another exception occurred:

Traceback (most recent call last):
  File "/home/username/.local/lib/python3.10/site-packages/airflow/models/taskinstance.py", line 767, in _execute_task
    result = _execute_callable(context=context, **execute_callable_kwargs)
  File "/home/username/.local/lib/python3.10/site-packages/airflow/models/taskinstance.py", line 733, in _execute_callable
    return ExecutionCallableRunner(
  File "/home/username/.local/lib/python3.10/site-packages/airflow/utils/operator_helpers.py", line 252, in run
    return self.func(*args, **kwargs)
  File "/home/username/.local/lib/python3.10/site-packages/airflow/models/baseoperator.py", line 406, in wrapper
    return func(self, *args, **kwargs)
  File "/home/username/.local/lib/python3.10/site-packages/airflow/operators/python.py", line 238, in execute
    return_value = self.execute_callable()
  File "/home/username/.local/lib/python3.10/site-packages/airflow/operators/python.py", line 256, in execute_callable
    return runner.run(*self.op_args, **self.op_kwargs)
  File "/home/username/.local/lib/python3.10/site-packages/airflow/utils/operator_helpers.py", line 252, in run
    return self.func(*args, **kwargs)
  File "/home/username/blackstraw/airflow/airflow/dags/data_ingestion_dag.py", line 45, in validate_data
    context = gx.get_context()
  File "/home/username/.local/lib/python3.10/site-packages/great_expectations/data_context/data_context/context_factory.py", line 263, in get_context
    context = _get_context(**kwargs)
  File "/home/username/.local/lib/python3.10/site-packages/great_expectations/data_context/data_context/context_factory.py", line 302, in _get_context
    file_context = _get_file_context(
  File "/home/username/.local/lib/python3.10/site-packages/great_expectations/data_context/data_context/context_factory.py", line 383, in _get_file_context
    return FileDataContext(
  File "/home/username/.local/lib/python3.10/site-packages/great_expectations/data_context/data_context/file_data_context.py", line 67, in __init__
    super().__init__(
  File "/home/username/.local/lib/python3.10/site-packages/great_expectations/data_context/data_context/serializable_data_context.py", line 68, in __init__
    super().__init__(runtime_environment=runtime_environment)
  File "/home/username/.local/lib/python3.10/site-packages/great_expectations/core/usage_statistics/usage_statistics.py", line 266, in usage_statistics_wrapped_method
    result = func(*args, **kwargs)
  File "/home/username/.local/lib/python3.10/site-packages/great_expectations/data_context/data_context/abstract_data_context.py", line 309, in __init__
    self._init_datasources()
  File "/home/username/.local/lib/python3.10/site-packages/great_expectations/data_context/data_context/abstract_data_context.py", line 4529, in _init_datasources
    ds = self._init_block_style_datasource(
  File "/home/username/.local/lib/python3.10/site-packages/great_expectations/data_context/data_context/abstract_data_context.py", line 4556, in _init_block_style_datasource
    return self._instantiate_datasource_from_config(
  File "/home/username/.local/lib/python3.10/site-packages/great_expectations/data_context/data_context/abstract_data_context.py", line 4577, in _instantiate_datasource_from_config
    datasource: Datasource = self._build_datasource_from_config(
  File "/home/username/.local/lib/python3.10/site-packages/great_expectations/data_context/data_context/abstract_data_context.py", line 4614, in _build_datasource_from_config
    datasource: Datasource = instantiate_class_from_config(
  File "/home/username/.local/lib/python3.10/site-packages/great_expectations/data_context/util.py", line 90, in instantiate_class_from_config
    class_instance = class_(**config_with_defaults)
  File "/home/username/.local/lib/python3.10/site-packages/great_expectations/datasource/new_datasource.py", line 483, in __init__
    self._init_data_connectors(data_connector_configs=data_connectors)
  File "/home/username/.local/lib/python3.10/site-packages/great_expectations/datasource/new_datasource.py", line 490, in _init_data_connectors
    self._build_data_connector_from_config(
  File "/home/username/.local/lib/python3.10/site-packages/great_expectations/datasource/new_datasource.py", line 237, in _build_data_connector_from_config
    new_data_connector: DataConnector = instantiate_class_from_config(
  File "/home/username/.local/lib/python3.10/site-packages/great_expectations/data_context/util.py", line 90, in instantiate_class_from_config
    class_instance = class_(**config_with_defaults)
  File "/home/username/.local/lib/python3.10/site-packages/great_expectations/datasource/data_connector/inferred_asset_sql_data_connector.py", line 104, in __init__
    self._refresh_introspected_assets_cache()
  File "/home/username/.local/lib/python3.10/site-packages/great_expectations/datasource/data_connector/inferred_asset_sql_data_connector.py", line 120, in _refresh_introspected_assets_cache
    introspected_table_metadata = self._introspect_db(
  File "/home/username/.local/lib/python3.10/site-packages/great_expectations/datasource/data_connector/inferred_asset_sql_data_connector.py", line 203, in _introspect_db
    inspector: sqlalchemy.Inspector = sa.inspect(engine)
  File "/home/username/.local/lib/python3.10/site-packages/sqlalchemy/inspection.py", line 64, in inspect
    ret = reg(subject)
  File "/home/username/.local/lib/python3.10/site-packages/sqlalchemy/engine/reflection.py", line 182, in _engine_insp
    return Inspector._construct(Inspector._init_engine, bind)
  File "/home/username/.local/lib/python3.10/site-packages/sqlalchemy/engine/reflection.py", line 117, in _construct
    init(self, bind)
  File "/home/username/.local/lib/python3.10/site-packages/sqlalchemy/engine/reflection.py", line 128, in _init_engine
    engine.connect().close()
  File "/home/username/.local/lib/python3.10/site-packages/sqlalchemy/engine/base.py", line 3325, in connect
    return self._connection_cls(self, close_with_result=close_with_result)
  File "/home/username/.local/lib/python3.10/site-packages/sqlalchemy/engine/base.py", line 96, in __init__
    else engine.raw_connection()
  File "/home/username/.local/lib/python3.10/site-packages/sqlalchemy/engine/base.py", line 3404, in raw_connection
    return self._wrap_pool_connect(self.pool.connect, _connection)
  File "/home/username/.local/lib/python3.10/site-packages/sqlalchemy/engine/base.py", line 3371, in _wrap_pool_connect
    return fn()
  File "/home/username/.local/lib/python3.10/site-packages/sqlalchemy/pool/base.py", line 327, in connect
    return _ConnectionFairy._checkout(self)
  File "/home/username/.local/lib/python3.10/site-packages/sqlalchemy/pool/base.py", line 894, in _checkout
    fairy = _ConnectionRecord.checkout(pool)
  File "/home/username/.local/lib/python3.10/site-packages/sqlalchemy/pool/base.py", line 493, in checkout
    rec = pool._do_get()
  File "/home/username/.local/lib/python3.10/site-packages/sqlalchemy/pool/impl.py", line 145, in _do_get
    with util.safe_reraise():
  File "/home/username/.local/lib/python3.10/site-packages/sqlalchemy/util/langhelpers.py", line 70, in __exit__
    compat.raise_(
  File "/home/username/.local/lib/python3.10/site-packages/sqlalchemy/util/compat.py", line 211, in raise_
    raise exception
  File "/home/username/.local/lib/python3.10/site-packages/sqlalchemy/pool/impl.py", line 143, in _do_get
    return self._create_connection()
  File "/home/username/.local/lib/python3.10/site-packages/sqlalchemy/pool/base.py", line 273, in _create_connection
    return _ConnectionRecord(self)
  File "/home/username/.local/lib/python3.10/site-packages/sqlalchemy/pool/base.py", line 388, in __init__
    self.__connect()
  File "/home/username/.local/lib/python3.10/site-packages/sqlalchemy/pool/base.py", line 686, in __connect
    self.dbapi_connection = connection = pool._invoke_creator(self)
  File "/home/username/.local/lib/python3.10/site-packages/airflow/models/taskinstance.py", line 3094, in signal_handler
    raise AirflowTaskTerminated("Task received SIGTERM signal")
airflow.exceptions.AirflowTaskTerminated: Task received SIGTERM signal
[2024-10-03T10:49:21.104+0530] {taskinstance.py:1225} INFO - Marking task as UP_FOR_RETRY. dag_id=data_ingestion_dag, task_id=validate_data, run_id=manual__2024-10-03T05:16:45.265780+00:00, execution_date=20241003T051645, start_date=20241003T051707, end_date=20241003T051921
[2024-10-03T10:49:21.138+0530] {taskinstance.py:340} INFO - ::group::Post task execution logs
