[2024-09-30T19:30:54.038+0530] {local_task_job_runner.py:123} INFO - ::group::Pre task execution logs
[2024-09-30T19:30:54.051+0530] {taskinstance.py:2612} INFO - Dependencies all met for dep_context=non-requeueable deps ti=<TaskInstance: test_postgres_connection_dag.extract_data manual__2024-09-30T14:00:50.477129+00:00 [queued]>
[2024-09-30T19:30:54.059+0530] {taskinstance.py:2612} INFO - Dependencies all met for dep_context=requeueable deps ti=<TaskInstance: test_postgres_connection_dag.extract_data manual__2024-09-30T14:00:50.477129+00:00 [queued]>
[2024-09-30T19:30:54.059+0530] {taskinstance.py:2865} INFO - Starting attempt 1 of 1
[2024-09-30T19:30:54.083+0530] {taskinstance.py:2888} INFO - Executing <Task(PythonOperator): extract_data> on 2024-09-30 14:00:50.477129+00:00
[2024-09-30T19:30:54.086+0530] {standard_task_runner.py:72} INFO - Started process 31701 to run task
[2024-09-30T19:30:54.091+0530] {standard_task_runner.py:104} INFO - Running: ['airflow', 'tasks', 'run', 'test_postgres_connection_dag', 'extract_data', 'manual__2024-09-30T14:00:50.477129+00:00', '--job-id', '15', '--raw', '--subdir', 'DAGS_FOLDER/test_postgres_connection_dag.py', '--cfg-path', '/tmp/tmpouj49fqh']
[2024-09-30T19:30:54.093+0530] {standard_task_runner.py:105} INFO - Job 15: Subtask extract_data
[2024-09-30T19:30:54.186+0530] {task_command.py:467} INFO - Running <TaskInstance: test_postgres_connection_dag.extract_data manual__2024-09-30T14:00:50.477129+00:00 [running]> on host Nithesh-Kumar.localdomain
[2024-09-30T19:30:54.283+0530] {taskinstance.py:3131} INFO - Exporting env vars: AIRFLOW_CTX_DAG_OWNER='airflow' AIRFLOW_CTX_DAG_ID='test_postgres_connection_dag' AIRFLOW_CTX_TASK_ID='extract_data' AIRFLOW_CTX_EXECUTION_DATE='2024-09-30T14:00:50.477129+00:00' AIRFLOW_CTX_TRY_NUMBER='1' AIRFLOW_CTX_DAG_RUN_ID='manual__2024-09-30T14:00:50.477129+00:00'
[2024-09-30T19:30:54.285+0530] {taskinstance.py:731} INFO - ::endgroup::
[2024-09-30T19:30:54.312+0530] {base.py:84} INFO - Retrieving connection 'source_***_conn'
[2024-09-30T19:30:54.340+0530] {taskinstance.py:3310} ERROR - Task failed with exception
Traceback (most recent call last):
  File "/home/username/.local/lib/python3.10/site-packages/airflow/models/taskinstance.py", line 767, in _execute_task
    result = _execute_callable(context=context, **execute_callable_kwargs)
  File "/home/username/.local/lib/python3.10/site-packages/airflow/models/taskinstance.py", line 733, in _execute_callable
    return ExecutionCallableRunner(
  File "/home/username/.local/lib/python3.10/site-packages/airflow/utils/operator_helpers.py", line 252, in run
    return self.func(*args, **kwargs)
  File "/home/username/.local/lib/python3.10/site-packages/airflow/models/baseoperator.py", line 406, in wrapper
    return func(self, *args, **kwargs)
  File "/home/username/.local/lib/python3.10/site-packages/airflow/operators/python.py", line 238, in execute
    return_value = self.execute_callable()
  File "/home/username/.local/lib/python3.10/site-packages/airflow/operators/python.py", line 256, in execute_callable
    return runner.run(*self.op_args, **self.op_kwargs)
  File "/home/username/.local/lib/python3.10/site-packages/airflow/utils/operator_helpers.py", line 252, in run
    return self.func(*args, **kwargs)
  File "/home/username/blackstraw/airflow/airflow/dags/test_postgres_connection_dag.py", line 14, in extract_data
    source_cursor.execute("SELECT * FROM source_table")
psycopg2.errors.UndefinedTable: relation "source_table" does not exist
LINE 1: SELECT * FROM source_table
                      ^

[2024-09-30T19:30:54.344+0530] {taskinstance.py:1225} INFO - Marking task as FAILED. dag_id=test_***_connection_dag, task_id=extract_data, run_id=manual__2024-09-30T14:00:50.477129+00:00, execution_date=20240930T140050, start_date=20240930T140054, end_date=20240930T140054
[2024-09-30T19:30:54.363+0530] {taskinstance.py:340} INFO - ::group::Post task execution logs
[2024-09-30T19:30:54.364+0530] {standard_task_runner.py:124} ERROR - Failed to execute job 15 for task extract_data (relation "source_table" does not exist
LINE 1: SELECT * FROM source_table
                      ^
; 31701)
Traceback (most recent call last):
  File "/home/username/.local/lib/python3.10/site-packages/airflow/task/task_runner/standard_task_runner.py", line 117, in _start_by_fork
    ret = args.func(args, dag=self.dag)
  File "/home/username/.local/lib/python3.10/site-packages/airflow/cli/cli_config.py", line 49, in command
    return func(*args, **kwargs)
  File "/home/username/.local/lib/python3.10/site-packages/airflow/utils/cli.py", line 115, in wrapper
    return f(*args, **kwargs)
  File "/home/username/.local/lib/python3.10/site-packages/airflow/cli/commands/task_command.py", line 483, in task_run
    task_return_code = _run_task_by_selected_method(args, _dag, ti)
  File "/home/username/.local/lib/python3.10/site-packages/airflow/cli/commands/task_command.py", line 256, in _run_task_by_selected_method
    return _run_raw_task(args, ti)
  File "/home/username/.local/lib/python3.10/site-packages/airflow/cli/commands/task_command.py", line 341, in _run_raw_task
    return ti._run_raw_task(
  File "/home/username/.local/lib/python3.10/site-packages/airflow/utils/session.py", line 97, in wrapper
    return func(*args, session=session, **kwargs)
  File "/home/username/.local/lib/python3.10/site-packages/airflow/models/taskinstance.py", line 3004, in _run_raw_task
    return _run_raw_task(
  File "/home/username/.local/lib/python3.10/site-packages/airflow/models/taskinstance.py", line 273, in _run_raw_task
    TaskInstance._execute_task_with_callbacks(
  File "/home/username/.local/lib/python3.10/site-packages/airflow/models/taskinstance.py", line 3158, in _execute_task_with_callbacks
    result = self._execute_task(context, task_orig)
  File "/home/username/.local/lib/python3.10/site-packages/airflow/models/taskinstance.py", line 3182, in _execute_task
    return _execute_task(self, context, task_orig)
  File "/home/username/.local/lib/python3.10/site-packages/airflow/models/taskinstance.py", line 767, in _execute_task
    result = _execute_callable(context=context, **execute_callable_kwargs)
  File "/home/username/.local/lib/python3.10/site-packages/airflow/models/taskinstance.py", line 733, in _execute_callable
    return ExecutionCallableRunner(
  File "/home/username/.local/lib/python3.10/site-packages/airflow/utils/operator_helpers.py", line 252, in run
    return self.func(*args, **kwargs)
  File "/home/username/.local/lib/python3.10/site-packages/airflow/models/baseoperator.py", line 406, in wrapper
    return func(self, *args, **kwargs)
  File "/home/username/.local/lib/python3.10/site-packages/airflow/operators/python.py", line 238, in execute
    return_value = self.execute_callable()
  File "/home/username/.local/lib/python3.10/site-packages/airflow/operators/python.py", line 256, in execute_callable
    return runner.run(*self.op_args, **self.op_kwargs)
  File "/home/username/.local/lib/python3.10/site-packages/airflow/utils/operator_helpers.py", line 252, in run
    return self.func(*args, **kwargs)
  File "/home/username/blackstraw/airflow/airflow/dags/test_postgres_connection_dag.py", line 14, in extract_data
    source_cursor.execute("SELECT * FROM source_table")
psycopg2.errors.UndefinedTable: relation "source_table" does not exist
LINE 1: SELECT * FROM source_table
                      ^

[2024-09-30T19:30:54.386+0530] {local_task_job_runner.py:266} INFO - Task exited with return code 1
[2024-09-30T19:30:54.402+0530] {taskinstance.py:3900} INFO - 0 downstream tasks scheduled from follow-on schedule check
[2024-09-30T19:30:54.418+0530] {local_task_job_runner.py:245} INFO - ::endgroup::
