[2024-10-01T13:09:16.650+0530] {local_task_job_runner.py:123} INFO - ::group::Pre task execution logs
[2024-10-01T13:09:16.659+0530] {taskinstance.py:2612} INFO - Dependencies all met for dep_context=non-requeueable deps ti=<TaskInstance: test_postgres_connection_dag.load_data manual__2024-10-01T07:39:00.777881+00:00 [queued]>
[2024-10-01T13:09:16.664+0530] {taskinstance.py:2612} INFO - Dependencies all met for dep_context=requeueable deps ti=<TaskInstance: test_postgres_connection_dag.load_data manual__2024-10-01T07:39:00.777881+00:00 [queued]>
[2024-10-01T13:09:16.664+0530] {taskinstance.py:2865} INFO - Starting attempt 1 of 1
[2024-10-01T13:09:16.690+0530] {taskinstance.py:2888} INFO - Executing <Task(PythonOperator): load_data> on 2024-10-01 07:39:00.777881+00:00
[2024-10-01T13:09:16.697+0530] {standard_task_runner.py:72} INFO - Started process 17854 to run task
[2024-10-01T13:09:16.702+0530] {standard_task_runner.py:104} INFO - Running: ['airflow', 'tasks', 'run', 'test_postgres_connection_dag', 'load_data', 'manual__2024-10-01T07:39:00.777881+00:00', '--job-id', '22', '--raw', '--subdir', 'DAGS_FOLDER/data_ingestion_dag.py', '--cfg-path', '/tmp/tmpvzc7o56r']
[2024-10-01T13:09:16.703+0530] {standard_task_runner.py:105} INFO - Job 22: Subtask load_data
[2024-10-01T13:09:16.743+0530] {task_command.py:467} INFO - Running <TaskInstance: test_postgres_connection_dag.load_data manual__2024-10-01T07:39:00.777881+00:00 [running]> on host Nithesh-Kumar.localdomain
[2024-10-01T13:09:16.967+0530] {taskinstance.py:3131} INFO - Exporting env vars: AIRFLOW_CTX_DAG_OWNER='airflow' AIRFLOW_CTX_DAG_ID='test_postgres_connection_dag' AIRFLOW_CTX_TASK_ID='load_data' AIRFLOW_CTX_EXECUTION_DATE='2024-10-01T07:39:00.777881+00:00' AIRFLOW_CTX_TRY_NUMBER='1' AIRFLOW_CTX_DAG_RUN_ID='manual__2024-10-01T07:39:00.777881+00:00'
[2024-10-01T13:09:16.968+0530] {taskinstance.py:731} INFO - ::endgroup::
[2024-10-01T13:09:16.982+0530] {base.py:84} INFO - Retrieving connection 'target_***_conn'
[2024-10-01T13:09:17.017+0530] {taskinstance.py:3310} ERROR - Task failed with exception
Traceback (most recent call last):
  File "/home/username/.local/lib/python3.10/site-packages/airflow/models/taskinstance.py", line 767, in _execute_task
    result = _execute_callable(context=context, **execute_callable_kwargs)
  File "/home/username/.local/lib/python3.10/site-packages/airflow/models/taskinstance.py", line 733, in _execute_callable
    return ExecutionCallableRunner(
  File "/home/username/.local/lib/python3.10/site-packages/airflow/utils/operator_helpers.py", line 252, in run
    return self.func(*args, **kwargs)
  File "/home/username/.local/lib/python3.10/site-packages/airflow/models/baseoperator.py", line 406, in wrapper
    return func(self, *args, **kwargs)
  File "/home/username/.local/lib/python3.10/site-packages/airflow/operators/python.py", line 238, in execute
    return_value = self.execute_callable()
  File "/home/username/.local/lib/python3.10/site-packages/airflow/operators/python.py", line 256, in execute_callable
    return runner.run(*self.op_args, **self.op_kwargs)
  File "/home/username/.local/lib/python3.10/site-packages/airflow/utils/operator_helpers.py", line 252, in run
    return self.func(*args, **kwargs)
  File "/home/username/blackstraw/airflow/airflow/dags/data_ingestion_dag.py", line 75, in load_data
    target_cursor.execute("""
psycopg2.errors.UniqueViolation: duplicate key value violates unique constraint "new_predictions_pkey"
DETAIL:  Key (id)=(6) already exists.

[2024-10-01T13:09:17.021+0530] {taskinstance.py:1225} INFO - Marking task as FAILED. dag_id=test_***_connection_dag, task_id=load_data, run_id=manual__2024-10-01T07:39:00.777881+00:00, execution_date=20241001T073900, start_date=20241001T073916, end_date=20241001T073917
[2024-10-01T13:09:17.044+0530] {taskinstance.py:340} INFO - ::group::Post task execution logs
[2024-10-01T13:09:17.044+0530] {standard_task_runner.py:124} ERROR - Failed to execute job 22 for task load_data (duplicate key value violates unique constraint "new_predictions_pkey"
DETAIL:  Key (id)=(6) already exists.
; 17854)
Traceback (most recent call last):
  File "/home/username/.local/lib/python3.10/site-packages/airflow/task/task_runner/standard_task_runner.py", line 117, in _start_by_fork
    ret = args.func(args, dag=self.dag)
  File "/home/username/.local/lib/python3.10/site-packages/airflow/cli/cli_config.py", line 49, in command
    return func(*args, **kwargs)
  File "/home/username/.local/lib/python3.10/site-packages/airflow/utils/cli.py", line 115, in wrapper
    return f(*args, **kwargs)
  File "/home/username/.local/lib/python3.10/site-packages/airflow/cli/commands/task_command.py", line 483, in task_run
    task_return_code = _run_task_by_selected_method(args, _dag, ti)
  File "/home/username/.local/lib/python3.10/site-packages/airflow/cli/commands/task_command.py", line 256, in _run_task_by_selected_method
    return _run_raw_task(args, ti)
  File "/home/username/.local/lib/python3.10/site-packages/airflow/cli/commands/task_command.py", line 341, in _run_raw_task
    return ti._run_raw_task(
  File "/home/username/.local/lib/python3.10/site-packages/airflow/utils/session.py", line 97, in wrapper
    return func(*args, session=session, **kwargs)
  File "/home/username/.local/lib/python3.10/site-packages/airflow/models/taskinstance.py", line 3004, in _run_raw_task
    return _run_raw_task(
  File "/home/username/.local/lib/python3.10/site-packages/airflow/models/taskinstance.py", line 273, in _run_raw_task
    TaskInstance._execute_task_with_callbacks(
  File "/home/username/.local/lib/python3.10/site-packages/airflow/models/taskinstance.py", line 3158, in _execute_task_with_callbacks
    result = self._execute_task(context, task_orig)
  File "/home/username/.local/lib/python3.10/site-packages/airflow/models/taskinstance.py", line 3182, in _execute_task
    return _execute_task(self, context, task_orig)
  File "/home/username/.local/lib/python3.10/site-packages/airflow/models/taskinstance.py", line 767, in _execute_task
    result = _execute_callable(context=context, **execute_callable_kwargs)
  File "/home/username/.local/lib/python3.10/site-packages/airflow/models/taskinstance.py", line 733, in _execute_callable
    return ExecutionCallableRunner(
  File "/home/username/.local/lib/python3.10/site-packages/airflow/utils/operator_helpers.py", line 252, in run
    return self.func(*args, **kwargs)
  File "/home/username/.local/lib/python3.10/site-packages/airflow/models/baseoperator.py", line 406, in wrapper
    return func(self, *args, **kwargs)
  File "/home/username/.local/lib/python3.10/site-packages/airflow/operators/python.py", line 238, in execute
    return_value = self.execute_callable()
  File "/home/username/.local/lib/python3.10/site-packages/airflow/operators/python.py", line 256, in execute_callable
    return runner.run(*self.op_args, **self.op_kwargs)
  File "/home/username/.local/lib/python3.10/site-packages/airflow/utils/operator_helpers.py", line 252, in run
    return self.func(*args, **kwargs)
  File "/home/username/blackstraw/airflow/airflow/dags/data_ingestion_dag.py", line 75, in load_data
    target_cursor.execute("""
psycopg2.errors.UniqueViolation: duplicate key value violates unique constraint "new_predictions_pkey"
DETAIL:  Key (id)=(6) already exists.

[2024-10-01T13:09:17.078+0530] {local_task_job_runner.py:266} INFO - Task exited with return code 1
[2024-10-01T13:09:17.089+0530] {taskinstance.py:3900} INFO - 0 downstream tasks scheduled from follow-on schedule check
[2024-10-01T13:09:17.089+0530] {local_task_job_runner.py:245} INFO - ::endgroup::
